Workbook

Sheet Balance
A1: Date | B1: Transaction | C1: Deposits | D1: Checks | E1: Balance | F1: Details
A4: 40908 | B4: Balance from 2011 | E4: =47276.67-3000-250-1000 -> 43026.67 | F4: 2011 Balance less 2012 Dues pd in 2011
A5: 40908 | B5: Deposit | C5: 3000 | E5: =+E4-D5+C5 -> 46026.67 | F5: City of Mankato (2012 Dues) pd in 2011
A6: 40908 | B6: Deposit | C6: 250 | E6: =+E5-D6+C6 -> 46276.67 | F6: Region Nine Development (2012 Dues) pd in 2011
A7: 40917 | B7: Deposit | C7: 1000 | E7: =+E6-D7+C7 -> 47276.67 | F7: City of North Mankato (2012 Dues)
A8: 40917 | B8: Deposit | C8: 5000 | E8: =+E7-D8+C8 -> 52276.67 | F8: Blue Earth County (2012 Dues)
A9: 40917 | B9: Deposit | C9: 1000 | E9: =+E8-D9+C9 -> 53276.67 | F9: City of Belle Plaine (2012 Dues)
A10: 40917 | B10: Deposit | C10: 3000 | E10: =+E9-D10+C10 -> 56276.67 | F10: City of Edina (2012 Dues)
A11: 40939 | B11: Transfer | C11: 5000 | E11: =+E10-D11+C11 -> 61276.67 | F11: Scott County (2012 Dues)
A12: 40926 | B12: Deposit | C12: 1000 | E12: =+E11-D12+C12 -> 62276.67 | F12: City of St Peter (2012 Dues)
A13: 40920 | B13: Deposit | C13: 1000 | E13: =+E12-D13+C13 -> 63276.67 | F13: City of Le Sueur (2012 Dues)
A14: 40927 | B14: Deposit | C14: 1000 | E14: =+E13-D14+C14 -> 64276.67 | F14: City of Prior Lake (2012 Dues)
A15: 40931 | B15: Deposit | C15: 3000 | E15: =+E14-D15+C15 -> 67276.67 | F15: City of Shakopee (2012 Dues)
A16: 40920 | B16: Deposit | C16: 3000 | E16: =+E15-D16+C16 -> 70276.67 | F16: City of Savage (2012 Dues)
... A21: 40931 | B21: Deposit | C21: 1000 | E21: =+E20-D21+C21 -> 73026.67 | F21: City of Jordan (2012 Dues)
E22: =+E21-D22+C22 -> 73026.67
E23: =+E22-D23+C23 -> 73026.67
E24: =+E23-D24+C24 -> 73026.67
E25: =+E24-D25+C25 -> 73026.67
A26: 40917 | B26: Deposit | C26: 1000 | E26: =+E25-D26+C26 -> 74026.67 | F26: LeSueur County (2012 Dues)
A27: 40939 | B27: Admin time | D27: 586.65 | E27: =+E26-D27+C27 -> 73440.02 | F27: Admin Support-Final January 2012
A28: 40939 | B28: Breakfast for event | D28: 303.38 | E28: =+E27-D28+C28 -> 73136.64 | F28: Dixie Blue BBQ LLC
A29: 40948 | B29: Deposit | C29: 25 | E29: =+E28-D29+C29 -> 73161.64 | F29: Kathleen Sheran
A30: 40966 | B30: Deposit | C30: 3000 | E30: =+E29-D30+C30 -> 76161.64 | F30: City of Bloomington (2012 Dues)
A31: 40940 | B31: WSB | D31: 1161 | E31: =+E30-D31+C31 -> 75000.64 | F31: Invoice 01557-020-20 Dec 1-Dec 31
A32: 40974 | B32: League of Mn Cities | D32: 850 | E32: =+E31-D32+C32 -> 74150.64 | F32: Invoice 39330 annual pay plan
A33: 40982 | B33: WSB | D33: 1293.74 | E33: =+E32-D33+C33 -> 72856.9 | F33: Invoice 01557-020-21 Jan. 01 to Jan. 31, 2012
A34: 40991 | B34: WSB | D34: 1293.75 | E34: =+E33-D34+C34 -> 71563.15 | F34: Invoice 01557-020-22 Feb. 1 to Feb. 29, 2012
A35: 41009 | B35: Deposit | C35: 500 | E35: =+E34-D35+C35 -> 72063.15 | F35: HDR Engineering, Inc. (April 2012 through March 2013 dues)
A36: 41051 | B36: Web Design | D36: 386.85 | E36: =+E35-D36+C36 -> 71676.3 | F36: Bufflehead Web Design Invoice March 4, 2012
A37: 41033 | B37: WSB | D37: 1293.76 | E37: =+E36-D37+C37 -> 70382.54 | F37: Invoice 01557-020-23 March 01 to March 31 2012
A38: 41051 | B38: Deposit | C38: 25 | E38: =+E37-D38+C38 -> 70407.54 | F38: Jordan Dental Care, PA (June 2012 through May 2013 dues)
A39: 41051 | B39: Deposit | C39: 500 | E39: =+E38-D39+C39 -> 70907.54 | F39: Greater Mankato Growth, Inc (June 2012 through May 2013 dues)
A40: 41088 | B40: Deposit | C40: 500 | E40: =+E39-D40+C40 -> 71407.54 | F40: Land to Air Express (Blue Earth / Blue Sky LLC June 2012 through May 2013-Silver Level
A41: 41068 | B41: WSB | D41: 1293.74 | E41: =+E40-D41+C41 -> 70113.8 | F41: Invoice 01557-020-24
A42: 41068 | B42: Region Nine Development Comm | D42: 121.14 | E42: =+E41-D42+C42 -> 69992.66 | F42: Feb-May Copies
A43: 41086 | B43: City of Jordan | D43: 95.2 | E43: =+E42-D43+C43 -> 69897.46 | F43: City of Jordan bars, Soda, Coffee 61412
A44: 41086 | B44: Karen Kreuser-CC | D44: 12.57 | E44: =+E43-D44+C44 -> 69884.89 | F44: Cookies for May 10th meeting
A45: 41112 | B45: WSB | D45: 1293.75 | E45: =+E44-D45+C45 -> 68591.14 | F45: Invoice 01557-020-25 May 1-May 31
A46: 41109 | B46: Bolton & Menk Dues | C46: 1000 | E46: =+E45-D46+C46 -> 69591.14 | F46: Bolton & Menk, Inc (June 2012 thru May 2013 dues)
...

Sheet Facilitator
D1: Consultant | I1: Travel | K1: Total | L1: Monthly | M1: Over (-) or
A2: Month | B2: Date | C2: Transaction | D2: Service | E2: Copies | F2: Telecopier | G2: Postage | H2: Telephone | I2: Expenses | J2: Other | K2: Expenses | L2: Budget | M2: under (+) budget
K4: =SUM(D4:J4) -> 0 | M4: =+L4-K4 -> 0
A5: 41244 | B5: 40940 | C5: 01557-020-20 | K5: 1161
A6: 40920 | B6: 40982 | C6: 01557-020-21 | K6: 1293.74
A7: 40940 | B7: 40991 | C7: 01557-020-22 | K7: 1293.75
A8: 40980 | B8: 41022 | C8: 01557-020-23 | K8: 1293.76
A9: 41011 | B9: 41068 | C9: 01557-020-24 | K9: 1293.74
A10: 41030 | B10: 41112 | C10: 01557-020-25 | K10: 1293.75
A11: 41061 | B11: 41115 | C11: 01557-020-26 | K11: 1293.76
C19: Yearly total | D19: =SUM(D4:D18) -> 0 | E19: =SUM(E4:E18) -> 0 | F19: =SUM(F4:F18) -> 0 | G19: =SUM(G4:G18) -> 0 | H19: =SUM(H4:H18) -> 0 | I19: =SUM(I4:I18) -> 0 | J19: =SUM(J4:J18) -> 0 | K19: =SUM(K4:K18) -> 8923.5 | L19: =SUM(L4:L18) -> 0 | M19: =+L19-K19 -> -8923.5

Sheet Budget
B1: Annual dues
A2: REVENUE | B2: Budgeted | C2: Collected
A3: Balance brought forward from 2011 | C3: =+Balance!E4 -> 43026.67
A4: Belle Plaine | B4: 1000 | C4: 1000
A5: Bloomington | B5: 3000 | C5: 3000
A6: Blue Earth County | B6: 5000 | C6: 5000
A7: Edina | B7: 3000 | C7: 3000
A8: Jordan | B8: 1000 | C8: 1000
A9: LeSueur | B9: 1000 | C9: 1000
A10: LeSueur County | B10: 1000 | C10: 1000
A11: Mankato | B11: 3000 | C11: 3000
A12: Nicollet County | B12: 1000 | C12: 1000
A13: North Mankato | B13: 1000 | C13: 1000
A14: Prior Lake | B14: 1000 | C14: 1000
A15: Region 9 | B15: 250 | C15: 250
... A20: Bolton & Menk, Inc. (Gold Level) | B20: 1000 | C20: 1000
A21: Louisville Township | C21: 250
A22: Spring Lake Township | C22: 250
A23: Sand Creek Township | C23: 250
A24: SMSC | C24: 0
A25: Kathleen Sheran | C25: 25
A26: HDR Engineering, Inc. | C26: 500
A27: Jordan Dental Care, PA (Special Level) June 2012 | C27: 25
A28: Greater Mankato Growth, Inc (Silver Level) June 2012 | C28: 500
A29: Land To Air Express (Silver Level) June 2012 | C29: 500
A30: TOTAL REVENUE | B30: =SUM(B4:B23) -> 34250 | C30: =SUM(C3:C29) -> 79576.67
A32: EXPENDITURES | B32: 2011 | C32: 2012
A33: Facilitator/consultant Expenses | B33: 0
A34: Facilitator/consultant | B34: 14906.75 | C34: =Facilitator!$K$19 -> 8923.5
A35: Graphics development | B35: 0 | C35: =+'Webb Site Development & Maint.'!D16 -> 506.7
A36: Printing & Mailing | B36: 0 | C36: =+Balance!D42+Balance!D51 -> 132.7
A37: Information & Website | B37: 552.25 | C37: 0
A38: Contingency
A39: Administrative Services (Scott County) | B39: 6865.3 | C39: =+Balance!D27-6.82-95.5 -> 484.33
A40: Insurance | B40: 850 | C40: 850
A41: IRC Study Data Update for Project Prioritization | B41: 1989.25 | C41: 0
A42: Events | B42: 812.06 | C42: =6.82+95.5+303.38+Balance!D43+Balance!D44 -> 513.47
A43: Federal HPP request prep/graphics | B43: 0
A44: Trip to DC/Meet w/Federal Delegation (3 members) | B44: 0
A45: TOTAL EXPENDITURES | B45: =SUM(B33:B44) -> 25975.61 | C45: =SUM(C33:C44) -> 11410.7
...

Sheet Webb Site Development & Maint.
A2: DATE | B2: Beginning balance from 2011 | D2: 13319.72
A3: 41029 | B3: Bufflehead Web Design | D3: 386.85
A4: 41121 | B4: Bufflehead Web Design | D4: 119.85
B16: Total | D16: =SUM(D3:D13) -> 506.7
B17: Beginning balance from 2011 | D17: 13319.72
B18: Total to date | D18: =SUM(D16:D17) -> 13826.42

Sheet DUES 2012
B1: US HWY 169 CORRIDOR COALITION INVOICE TRACKING | I1: 2009 | M1: 2011 | N1: 2011 | P1: 2012 | Q1: 2012
B2: Invoice Sent to: | C2: City | D2: Set amount | E2: Amount Billed | F2: Received JPA | G2: Date Mailed | H2: Date Paid | I2: Amount Paid | K2: Amount Billed | L2: Date Mailed | M2: Date Paid | N2: Amount Paid | O2: Date Mailed | P2: Date Paid | Q2: Amount Paid
B4: Mr. David Murphy | C4: Belle Plaine | D4: 1000 | E4: 1000 | G4: 40004 | H4: 40018 | I4: 1000 | K4: 1000 | L4: 40522 | M4: 40548 | N4: 1000 | O4: 40897 | P4: 40917 | Q4: 1000
B5: Jim Gates | C5: Bloomington | D5: 3000 | E5: 3000 | F5: X | G5: 40004 | H5: 40031 | I5: 3000 | K5: 3000 | L5: 40522 | M5: 40588 | N5: 3000 | O5: 40897 | P5: 40917 | Q5: 3000
C6: Eden Prairie | D6: 3000 | E6: 0 | K6: 3000 | L6: 40522 | O6: 40897
B7: Mr. Hughes | C7: Edina | D7: 3000 | E7: 3000 | F7: X | G7: 40004 | H7: 40018 | I7: 3000 | K7: 3000 | L7: 40522 | M7: 40553 | N7: 3000 | O7: 40897 | P7: 40940 | Q7: 3000
C8: Golden Valley | D8: 1000 | E8: 0 | K8: 1000 | L8: 40522 | O8: 40897
C9: Hopkins | D9: 1000 | E9: 0 | K9: 1000 | L9: 40522 | O9: 40897
B10: Mr. Ed Shukle | C10: Jordan | D10: 1000 | E10: 1000 | F10: X | G10: 40004 | H10: 40016 | I10: 1000 | K10: 1000 | L10: 40522 | M10: 40534 | N10: 1000 | O10: 40897 | P10: 40931 | Q10: 1000
B11: Mr. Richard Almich | C11: Le Sueur | D11: 1000 | E11: 1000 | F11: X | G11: 40004 | H11: 40023 | I11: 1000 | K11: 1000 | L11: 40522 | M11: 40556 | N11: 1000 | O11: 40897 | P11: 40920 | Q11: 1000
B12: Pat Hentges | C12: Mankato | D12: 0 | E12: 0 | I12: 0 | K12: 3000 | L12: 40522 | M12: 40535 | N12: 3000 | O12: 40897 | P12: 40848 | Q12: 3000
B13: Steve Mork | C13: North Mankato | D13: 1000 | E13: 1000 | F13: X | G13: 40028 | H13: 40045 | I13: 1000 | K13: 1000 | L13: 40522 | M13: 40534 | N13: 1000 | O13: 40897 | P13: 40917 | Q13: 1000
B14: Jane Kansier | C14: Prior Lake | D14: 1000 | E14: 1000 | F14: X | G14: 40004 | H14: 40023 | I14: 1000 | K14: 1000 | L14: 40522 | M14: 40567 | N14: 1000 | O14: 40897 | P14: 40927 | Q14: 1000
B15: John Powell | C15: Savage | D15: 3000 | E15: 3000 | F15: X | G15: 40004 | H15: 40030 | I15: 3000 | K15: 3000 | L15: 40522 | M15: 40548 | N15: 3000 | O15: 40897 | P15: 40920 | Q15: 3000
B16: Mr. Mark McNeill | C16: Shakopee | D16: 3000 | E16: 3000 | F16: X | G16: 40004 | H16: 40035 | I16: 3000 | K16: 3000 | L16: 40522 | M16: 40567 | N16: 3000 | O16: 40897 | P16: 40931 | Q16: 3000
B17: Lewis Giesking | C17: St Peter | D17: 1000 | E17: 1000 | F17: X | G17: 40049 | H17: 40074 | I17: 1000 | K17: 1000 | L17: 40522 | M17: 40556 | N17: 1000 | O17: 40897 | P17: 40926 | Q17: 1000
C18: County
B20: Mr. Al Forsberg | C20: Blue Earth | D20: 5000 | E20: 5000 | F20: X | G20: 40004 | H20: 40022 | I20: 5000 | K20: 5000 | L20: 40522 | M20: 40546 | N20: 5000 | O20: 40897 | P20: 40917 | Q20: 5000
B21: Mr. Darrell Pettis | C21: Le Sueur | D21: 1000 | E21: 1000 | F21: X | G21: 40004 | H21: 40008 | I21: 1000 | K21: 1000 | L21: 40522 | M21: 40540 | N21: 1000 | O21: 40897 | P21: 40917 | Q21: 1000
B22: Seth Greenwood | C22: Nicollet | D22: 0 | E22: 0 | F22: X | K22: 1000 | L22: 40522 | M22: 40546 | N22: 1000 | O22: 40897 | P22: 40935 | Q22: 1000
B23: Ms. Lisa Freese | C23: Scott | D23: 10000 | E23: 10000 | F23: X | G23: 40004 | H23: 40065 | I23: 10000 | K23: 5000 | L23: 40522 | M23: 40553 | N23: 5000 | O23: 40897 | P23: 40939 | Q23: 5000
C24: Region 9
B26: Lu Vanderwerf | C26: Region 9 | D26: 250 | E26: 250 | F26: X | G26: 40004 | H26: 40168 | I26: 250 | K26: 250 | L26: 40522 | M26: 40539 | N26: 250 | O26: 40897 | P26: 40904 | Q26: 250
C27: Township
B29: LuAnne Lemke | C29: Louisville Township | D29: 250 | E29: 250 | F29: X | I29: 250 | K29: 250 | L29: 40618 | M29: 40618 | N29: 250 | O29: 40897 | P29: 40920 | Q29: 250
B30: Kathy Nielsen | C30: Spring Lake Township | D30: 250 | E30: 250 | F30: X | I30: 250 | K30: 250 | L30: 40618 | M30: 40618 | N30: 250 | O30: 40897 | P30: 40926 | Q30: 250
B31: Rita Tauer | C31: Sand Creek Township | D31: 250 | E31: 250 | F31: X | I31: 250 | K31: 250 | L31: 40618 | M31: 40618 | N31: 250 | O31: 40897 | P31: 40931 | Q31: 250
C32: Affilate Members Gold Level
B33: D. Joseph Dunean | C33: Bolton & Menk, Inc | K33: 1000 | L33: 40679 | M33: 40694 | N33: 1000 | P33: 41109 | Q33: 1000
B34: Khani Sahebjam & Kian Sabeti | C34: HDR Engineering, Inc | K34: 1000 | L34: 40679 | M34: 40694 | N34: 1000 | P34: 41009 | Q34: 500
B35: Bill Rudnicki | C35: Shakopee Mdewakauton Sioux Community | K35: 1000 | L35: 40831 | M35: 40831 | N35: 1000 | O35: 41153 | Q35: 1000
C36: Affilate Members Silver Level
B37: Jonathan Zierdt | C37: Greater Mankato Growth, Inc | P37: 41051 | Q37: 500
C38: Affilate Members Special Level
B39: Bonnie Buckanan | C39: Land To Air Express | Q39: 500
C40: Affilate Members Silver Level
B41: Dr. Elizabeth Thelemann | C41: Jordan Dental Care, P.A. | P41: 41051 | Q41: 25
C42: Indivitual Members
C43: Kathleen Sheran | P43: 40940 | Q43: 25
B45: Total | D45: =SUM(D3:D26) -> 39250 | E45: =SUM(E3:E26) -> 34250 | I45: =SUM(I4:I26) -> 34250 | K45: =SUM(K3:K35)-3000-2000 -> 37000 | N45: =SUM(N3:N35) -> 37000 | Q45: =SUM(Q3:Q44) -> 37550
